root@ASOKRMNWB102 ~]# tail -n 40 /root/.local/state/zabbix-cli/log/zabbix-cli.log
  File "/usr/local/lib/python3.9/site-packages/zabbix_cli/auth.py", line 124, in login
    raise AuthError(
zabbix_cli.exceptions.AuthError: No authentication method succeeded for http://184.106.4.20. Check the logs for more information.
2025-04-17 10:55:22,282 [zabbix_cli.pyzabbix.client][None][INFO][client.py:248 __init__]: JSON-RPC Server Endpoint: http://184.106.4.20/api_jsonrpc.php
2025-04-17 10:55:22,283 [zabbix_cli][None][INFO][auth.py:243 login]: Logging in to http://184.106.4.20
2025-04-17 10:55:22,283 [zabbix_cli.auth][None][INFO][auth.py:209 load_auth_token_file]: No auth token file found. Searched in /root/.local/share/zabbix-cli/.zabbix-cli_auth_token, /root/.zabbix-cli_auth_token
2025-04-17 10:55:22,285 [zabbix_cli.auth][None][WARNING][auth.py:116 login]: Failed to log in with _get_username_password_config: Failed to get Zabbix API version: Failed to send request to http://184.106.4.20/api_jsonrpc.php (apiinfo.version) with params {}
2025-04-17 10:55:22,285 [zabbix_cli.auth][None][INFO][auth.py:220 load_auth_file]: No auth file found. Searched in /root/.local/share/zabbix-cli/.zabbix-cli_auth, /root/.zabbix-cli_auth
2025-04-17 10:55:51,515 [zabbix_cli.auth][None][WARNING][auth.py:116 login]: Failed to log in with _get_username_password_prompt: Failed to get Zabbix API version: Failed to send request to http://184.106.4.20/api_jsonrpc.php (apiinfo.version) with params {}
2025-04-17 10:55:51,516 [zabbix_cli][None][ERROR][console.py:161 exit_err]: No authentication method succeeded for http://184.106.4.20. Check the logs for more information.
Traceback (most recent call last):
  File "/usr/local/lib/python3.9/site-packages/zabbix_cli/main.py", line 242, in main
    app()
  File "/usr/local/lib/python3.9/site-packages/typer/main.py", line 338, in __call__
    raise e
  File "/usr/local/lib/python3.9/site-packages/typer/main.py", line 321, in __call__
    return get_command(self)(*args, **kwargs)
  File "/usr/local/lib/python3.9/site-packages/click/core.py", line 1157, in __call__
    return self.main(*args, **kwargs)
  File "/usr/local/lib/python3.9/site-packages/typer/core.py", line 728, in main
    return _main(
  File "/usr/local/lib/python3.9/site-packages/typer/core.py", line 197, in _main
    rv = self.invoke(ctx)
  File "/usr/local/lib/python3.9/site-packages/click/core.py", line 1666, in invoke
    rv = super().invoke(ctx)
  File "/usr/local/lib/python3.9/site-packages/click/core.py", line 1434, in invoke
    return ctx.invoke(self.callback, **ctx.params)
  File "/usr/local/lib/python3.9/site-packages/click/core.py", line 783, in invoke
    return __callback(*args, **kwargs)
  File "/usr/local/lib/python3.9/site-packages/typer/main.py", line 703, in wrapper
    return callback(**use_params)
  File "/usr/local/lib/python3.9/site-packages/zabbix_cli/main.py", line 154, in main_callback
    state.login()
  File "/usr/local/lib/python3.9/site-packages/zabbix_cli/state.py", line 227, in login
    auth.login(self.client, self.config)
  File "/usr/local/lib/python3.9/site-packages/zabbix_cli/auth.py", line 245, in login
    token = auth.login()
  File "/usr/local/lib/python3.9/site-packages/zabbix_cli/auth.py", line 124, in login
    raise AuthError(
zabbix_cli.exceptions.AuthError: No authentication method succeeded for http://184.106.4.20. Check the logs for more information.
